Workbook

Sheet Assumptions
A1: Assunzioni modello SRL / SSD / Immobiliare
A3: Categoria | B3: Voce | C3: Base input | D3: Valore input | E3: Valore netto | F3: IVA | G3: Cash lordo | H3: Fonte
A4: Core | B4: Aliquota IVA | C4: Percentuale | D4: 0.22 | E4: =D4 -> 0.22 | F4: =0 -> 0 | G4: =D4 -> 0.22 | H4: Assunzione base
A5: Ricavi | B5: Ricavi diretti SRL | C5: Net + VAT | D5: 1700000 | E5: =IF(C5="Gross incl. VAT",D5/(1+$D$4),D5) -> 1700000 | F5: =IF(C5="Gross incl. VAT",D5-E5,IF(C5="Net + VAT",D5*$D$4,0)) -> 374000 | G5: =IF(C5="Gross incl. VAT",D5,IF(C5="Net + VAT",D5*(1+$D$4),D5)) -> 2074000 | H5: Utente
A6: Ricavi | B6: Ricavi esterni SSD | C6: No VAT | D6: 700000 | E6: =IF(C6="Gross incl. VAT",D6/(1+$D$4),D6) -> 700000 | F6: =IF(C6="Gross incl. VAT",D6-E6,IF(C6="Net + VAT",D6*$D$4,0)) -> 0 | G6: =IF(C6="Gross incl. VAT",D6,IF(C6="Net + VAT",D6*(1+$D$4),D6)) -> 700000 | H6: Utente
A7: Intercompany | B7: Canone spazi SSD -> SRL | C7: Net + VAT | D7: 200000 | E7: =IF(C7="Gross incl. VAT",D7/(1+$D$4),D7) -> 200000 | F7: =IF(C7="Gross incl. VAT",D7-E7,IF(C7="Net + VAT",D7*$D$4,0)) -> 44000 | G7: =IF(C7="Gross incl. VAT",D7,IF(C7="Net + VAT",D7*(1+$D$4),D7)) -> 244000 | H7: Assunzione condivisa
A8: Intercompany | B8: Servizi SRL -> SSD | C8: Net + VAT | D8: 230000 | E8: =IF(C8="Gross incl. VAT",D8/(1+$D$4),D8) -> 230000 | F8: =IF(C8="Gross incl. VAT",D8-E8,IF(C8="Net + VAT",D8*$D$4,0)) -> 50600 | G8: =IF(C8="Gross incl. VAT",D8,IF(C8="Net + VAT",D8*(1+$D$4),D8)) -> 280600 | H8: Assunzione condivisa
A9: Intercompany | B9: Locazione SRL -> Immobiliare | C9: Net + VAT | D9: 300000 | E9: =IF(C9="Gross incl. VAT",D9/(1+$D$4),D9) -> 300000 | F9: =IF(C9="Gross incl. VAT",D9-E9,IF(C9="Net + VAT",D9*$D$4,0)) -> 66000 | G9: =IF(C9="Gross incl. VAT",D9,IF(C9="Net + VAT",D9*(1+$D$4),D9)) -> 366000 | H9: Utente
A10: Intercompany | B10: Servizi impianti SRL -> Immobiliare | C10: Net + VAT | D10: 150000 | E10: =IF(C10="Gross incl. VAT",D10/(1+$D$4),D10) -> 150000 | F10: =IF(C10="Gross incl. VAT",D10-E10,IF(C10="Net + VAT",D10*$D$4,0)) -> 33000 | G10: =IF(C10="Gross incl. VAT",D10,IF(C10="Net + VAT",D10*(1+$D$4),D10)) -> 183000 | H10: Utente
A11: Costi SRL | B11: Personale SRL | C11: No VAT | D11: 380000 | E11: =IF(C11="Gross incl. VAT",D11/(1+$D$4),D11) -> 380000 | F11: =IF(C11="Gross incl. VAT",D11-E11,IF(C11="Net + VAT",D11*$D$4,0)) -> 0 | G11: =IF(C11="Gross incl. VAT",D11,IF(C11="Net + VAT",D11*(1+$D$4),D11)) -> 380000 | H11: Utente
A12: Costi SRL | B12: Energia SRL | C12: Gross incl. VAT | D12: 140000 | E12: =IF(C12="Gross incl. VAT",D12/(1+$D$4),D12) -> 114754.1 | F12: =IF(C12="Gross incl. VAT",D12-E12,IF(C12="Net + VAT",D12*$D$4,0)) -> 25245.902 | G12: =IF(C12="Gross incl. VAT",D12,IF(C12="Net + VAT",D12*(1+$D$4),D12)) -> 140000 | H12: Utente
A13: Costi SRL | B13: Acqua SRL | C13: Gross incl. VAT | D13: 30000 | E13: =IF(C13="Gross incl. VAT",D13/(1+$D$4),D13) -> 24590.164 | F13: =IF(C13="Gross incl. VAT",D13-E13,IF(C13="Net + VAT",D13*$D$4,0)) -> 5409.8361 | G13: =IF(C13="Gross incl. VAT",D13,IF(C13="Net + VAT",D13*(1+$D$4),D13)) -> 30000 | H13: Utente
A14: Costi SRL | B14: Pulizie SRL | C14: Gross incl. VAT | D14: 100000 | E14: =IF(C14="Gross incl. VAT",D14/(1+$D$4),D14) -> 81967.213 | F14: =IF(C14="Gross incl. VAT",D14-E14,IF(C14="Net + VAT",D14*$D$4,0)) -> 18032.787 | G14: =IF(C14="Gross incl. VAT",D14,IF(C14="Net + VAT",D14*(1+$D$4),D14)) -> 100000 | H14: Utente
A15: Costi SRL | B15: Commercialista SRL | C15: Net + VAT | D15: 12000 | E15: =IF(C15="Gross incl. VAT",D15/(1+$D$4),D15) -> 12000 | F15: =IF(C15="Gross incl. VAT",D15-E15,IF(C15="Net + VAT",D15*$D$4,0)) -> 2640 | G15: =IF(C15="Gross incl. VAT",D15,IF(C15="Net + VAT",D15*(1+$D$4),D15)) -> 14640 | H15: Utente
A16: Costi SRL | B16: Legale SRL | C16: Net + VAT | D16: 15000 | E16: =IF(C16="Gross incl. VAT",D16/(1+$D$4),D16) -> 15000 | F16: =IF(C16="Gross incl. VAT",D16-E16,IF(C16="Net + VAT",D16*$D$4,0)) -> 3300 | G16: =IF(C16="Gross incl. VAT",D16,IF(C16="Net + VAT",D16*(1+$D$4),D16)) -> 18300 | H16: Utente
... A24: Costi SSD | B24: Affiliazioni e tesseramenti SSD | C24: No VAT | D24: 10000 | E24: =IF(C24="Gross incl. VAT",D24/(1+$D$4),D24) -> 10000 | F24: =IF(C24="Gross incl. VAT",D24-E24,IF(C24="Net + VAT",D24*$D$4,0)) -> 0 | G24: =IF(C24="Gross incl. VAT",D24,IF(C24="Net + VAT",D24*(1+$D$4),D24)) -> 10000 | H24: Utente
A25: Compenso Amm. | B25: Compenso amministratore SRL | C25: Net + VAT | D25: 25000 | E25: 25000 | F25: 0 | G25: 25000 | H25: Utente
A26: Ammortamenti | B26: Ammortamenti SRL | C26: No VAT | D26: 200000 | E26: 200000 | F26: 0 | G26: 200000 | H26: Utente
A27: Costi Immob. | B27: Costi operativi Immobiliare | C27: No VAT | D27: 80000 | E27: 80000 | F27: 0 | G27: 80000 | H27: Utente
A28: Costi Immob. | B28: Ammortamenti Immobiliare | C28: No VAT | D28: 100000 | E28: 100000 | F28: 0 | G28: 100000 | H28: Utente
A29: TFM | B29: TFM amministratore SRL (annuo) | C29: No VAT | D29: 6000 | E29: 6000 | F29: 0 | G29: 6000 | H29: Difendibile - complessità gruppo multi-entità
A30: Capex SRL | B30: Investimenti annui SRL (capex) | C30: Net + VAT | D30: 200000 | E30: 200000 | F30: 44000 | G30: 244000 | H30: Utente — coerente con ammortamenti

Sheet SRL P&L
A1: SRL - Conto economico e bridge IVA
A3: Voce | B3: Importo netto | C3: % ricavi SRL | D3: Note | F3: Bridge IVA SRL | G3: Importo | H3: Note
A4: Ricavi | F4: IVA a debito su ricavi diretti SRL | G4: =Assumptions!F5 -> 374000
A5: Ricavi diretti SRL | B5: =Assumptions!E5 -> 1700000 | C5: =IF($B$9=0,0,B5/$B$9) -> 0.79812207 | D5: Ricavi commerciali diretti | F5: IVA a debito su canone spazi SSD | G5: =Assumptions!F7 -> 44000
A6: Canone spazi da SSD | B6: =Assumptions!E7 -> 200000 | C6: =IF($B$9=0,0,B6/$B$9) -> 0.093896714 | D6: Intercompany | F6: IVA a debito su servizi a SSD | G6: =Assumptions!F8 -> 50600
A7: Servizi a SSD | B7: =Assumptions!E8 -> 230000 | C7: =IF($B$9=0,0,B7/$B$9) -> 0.10798122 | D7: Intercompany | F7: Totale IVA a debito | G7: =SUM(G4:G6) -> 468600
C8: =IF($B$9=0,0,B8/$B$9) -> 0 | F8: IVA a credito costi SRL | G8: =SUM(Assumptions!F12:F21) -> 89828.525
A9: Totale ricavi SRL | B9: =SUM(B5:B7) -> 2130000 | C9: =IF($B$9=0,0,B9/$B$9) -> 1 | F9: IVA a credito su Capex (200k x 22%) | G9: 44000
A10: Totale ricavi SRL | F10: IVA a credito locazione + impianti | G10: =SUM(Assumptions!F9:F10) -> 99000
F11: Totale IVA a credito | G11: =SUM(G8:G10) -> 232828.52
A12: Costi operativi | F12: IVA netta da versare SRL | G12: =G7-G11 -> 235771.48
F13: → IVA capex già inclusa nel credito sopra
F14: IVA netta da versare (finale) | G14: =G12 -> 235771.48
A15: Personale SRL | B15: =Assumptions!E11 -> 380000 | C15: =IF($B$9=0,0,B12/$B$9) -> 0
A16: Energia SRL | B16: =Assumptions!E12 -> 114754.1 | C16: =IF($B$9=0,0,B13/$B$9) -> 0
A17: Acqua SRL | B17: =Assumptions!E13 -> 24590.164 | C17: =IF($B$9=0,0,B14/$B$9) -> 0
A18: Pulizie SRL | B18: =Assumptions!E14 -> 81967.213 | C18: =IF($B$9=0,0,B15/$B$9) -> 0.17840376
A19: Commercialista SRL | B19: =Assumptions!E15 -> 12000 | C19: =IF($B$9=0,0,B16/$B$9) -> 0.053875164
A20: Legale SRL | B20: =Assumptions!E16 -> 15000 | C20: =IF($B$9=0,0,B17/$B$9) -> 0.011544678
A21: Commissioni pagamenti SRL | B21: =Assumptions!E17 -> 30000 | C21: =IF($B$9=0,0,B18/$B$9) -> 0.03848226
A22: Marketing SRL | B22: =Assumptions!E18 -> 30000 | C22: =IF($B$9=0,0,B19/$B$9) -> 0.0056338028
A23: Software vari SRL | B23: =Assumptions!E19 -> 30000 | C23: =IF($B$9=0,0,B20/$B$9) -> 0.0070422535
A24: Manutenzione SRL | B24: =Assumptions!E20 -> 30000 | C24: =IF($B$9=0,0,B21/$B$9) -> 0.014084507
A25: Acquisti vari SRL | B25: =Assumptions!E21 -> 40000 | C25: =IF($B$9=0,0,B22/$B$9) -> 0.014084507
A26: Locazione da Immobiliare | B26: =Assumptions!E9 -> 300000 | C26: =IF($B$9=0,0,B23/$B$9) -> 0.014084507
A27: Servizi impianti da Immobiliare | B27: =Assumptions!E10 -> 150000 | C27: =IF($B$9=0,0,B24/$B$9) -> 0.014084507
A28: Totale costi SRL | B28: =SUM(B12:B27)+B30+B31 -> 1269311.5 | C28: =IF($B$9=0,0,B25/$B$9) -> 0.018779343
A30: Compenso amministratore | B30: 25000 | C30: =IF($B$9=0,0,B27/$B$9) -> 0.070422535 | D30: Costo deducibile SRL
A31: TFM amministratore | B31: 6000 | C31: =IF($B$9=0,0,B28/$B$9) -> 0.59592088 | D31: Accantonamento annuo — tassazione separata a fine mandato
A34: EBITDA SRL | B34: =B9-B28 -> 860688.52 | C34: =IF($B$9=0,0,B34/$B$9) -> 0.40407912 | D34: Prima di ammortamenti, interessi e imposte
A35: Ammortamenti SRL | B35: -200000 | C35: =IF($B$9=0,0,B35/$B$9) -> -0.093896714 | D35: Impianti, attrezzature, migliorie
A36: EBIT SRL | B36: =B34+B35 -> 660688.52 | C36: =IF($B$9=0,0,B36/$B$9) -> 0.31018241 | D36: Prima di interessi e imposte
A37: IRES (24%) | B37: =IF(B36>0,-B36*0.24,0) -> -158565.25 | C37: =IF($B$9=0,0,B37/$B$9) -> -0.074443777 | D37: Aliquota ordinaria
A38: IRAP (3.9%) | B38: =IF(B36>0,-B36*0.039,0) -> -25766.852 | C38: =IF($B$9=0,0,B38/$B$9) -> -0.012097114 | D38: Approssimazione — base IRAP ≠ EBIT
A39: Utile netto SRL | B39: =B36+B37+B38 -> 476356.43 | C39: =IF($B$9=0,0,B39/$B$9) -> 0.22364151 | D39: Disponibile per dividendi / holding
A42: ── CASH FLOW OPERATIVO (stima) ──────────────────
A43: Utile netto SRL | B43: =B39 -> 476356.43 | C43: =IF($B$9=0,0,B43/$B$9) -> 0.22364151
A44: + Ammortamenti (non-cash) | B44: =-B35 -> 200000 | C44: =IF($B$9=0,0,B44/$B$9) -> 0.093896714 | D44: Reintegro cassa — costo non monetario
A45: Cash flow ante capex | B45: =B43+B44 -> 676356.43 | C45: =IF($B$9=0,0,B45/$B$9) -> 0.31753823
A47: ── CAPEX E IVA ──────────────────────────────────
...

Sheet SSD P&L
A1: SSD - Conto economico e IVA non detraibile
A3: Voce | B3: Importo netto | C3: % ricavi SSD | D3: Note | F3: Cash IVA SSD | G3: Importo | H3: Note
A4: Ricavi | F4: IVA su canone spazi SRL | G4: =Assumptions!F7 -> 44000
A5: Ricavi esterni SSD | B5: =Assumptions!E6 -> 700000 | C5: =IF($B$5=0,0,B5/$B$5) -> 1 | D5: Scuola nuoto / attività sportiva | F5: IVA su servizi SRL | G5: =Assumptions!F8 -> 50600
F6: IVA non detraibile SSD | G6: =SUM(G4:G5) -> 94600 | H6: Costo finanziario, non P&L
A7: Costi SSD
A8: Personale SSD | B8: =Assumptions!E22 -> 250000 | C8: =IF($B$5=0,0,B8/$B$5) -> 0.35714286
A9: Materiale sportivo SSD | B9: =Assumptions!E23 -> 10000 | C9: =IF($B$5=0,0,B9/$B$5) -> 0.014285714
A10: Affiliazioni e tesseramenti SSD | B10: =Assumptions!E24 -> 10000 | C10: =IF($B$5=0,0,B10/$B$5) -> 0.014285714
A11: Canone spazi verso SRL | B11: =Assumptions!E7 -> 200000 | C11: =IF($B$5=0,0,B11/$B$5) -> 0.28571429 | D11: Intercompany
A12: Servizi verso SRL | B12: =Assumptions!E8 -> 230000 | C12: =IF($B$5=0,0,B12/$B$5) -> 0.32857143 | D12: Intercompany
C13: =IF($B$5=0,0,B13/$B$5) -> 0
A14: Totale costi SSD | B14: =SUM(B8:B12) -> 700000 | C14: =IF($B$5=0,0,B14/$B$5) -> 1
C15: =IF($B$5=0,0,B15/$B$5) -> 0
A16: EBITDA SSD | B16: =B5-B14 -> 0 | C16: =IF($B$5=0,0,B16/$B$5) -> 0 | D16: Obiettivo: break-even

Sheet Immobiliare
A1: Immobiliare - ricavi intercompany
A3: Voce | B3: Importo netto | C3: % ricavi immob. | D3: Note
A4: Locazione a SRL | B4: =Assumptions!E9 -> 300000 | C4: =IF($B$6=0,0,B4/$B$6) -> 0.66666667
A5: Servizi impianti a SRL | B5: =Assumptions!E10 -> 150000 | C5: =IF($B$6=0,0,B5/$B$6) -> 0.33333333
A6: Totale ricavi Immobiliare | B6: =SUM(B4:B5) -> 450000 | C6: =IF($B$6=0,0,B6/$B$6) -> 1
A8: Costi operativi Immobiliare | B8: -80000 | C8: =IF($B$6=0,0,B8/$B$6) -> -0.17777778 | D8: IMU, manutenzioni, assicurazioni, spese
A10: Ammortamenti Immobiliare | B10: -100000 | C10: =IF($B$6=0,0,B10/$B$6) -> -0.22222222 | D10: Fabbricato, impianti fissi
A11: EBITDA Immobiliare | B11: =B6+B8 -> 370000 | C11: =IF($B$6=0,0,B11/$B$6) -> 0.82222222 | D11: Prima di ammortamenti
A12: EBIT Immobiliare | B12: =B11+B10 -> 270000 | C12: =IF($B$6=0,0,B12/$B$6) -> 0.6 | D12: Prima di interessi e imposte
A13: IRES (24%) | B13: =IF(B12>0,-B12*0.24,0) -> -64800
A14: Utile netto Immobiliare | B14: =B12+B13 -> 205200

Sheet Summary
A1: Summary - KPI e incidenze
A3: KPI | B3: SRL | C3: SSD | D3: Immobiliare | E3: Consolidato* | G3: Incidenze su base ricavi | H3: SRL | I3: SSD | J3: Consolidato
A4: Ricavi | B4: ='SRL P&L'!B9 -> 2130000 | C4: ='SSD P&L'!B5 -> 700000 | D4: =Immobiliare!B6 -> 450000 | E4: =Assumptions!E5+Assumptions!E6 -> 2400000 | G4: Personale % | H4: =IFERROR(Assumptions!E11/'SRL P&L'!B9,"-") -> 0.17840376 | I4: =Assumptions!E22/'SSD P&L'!B5 -> 0.35714286 | J4: =(Assumptions!E11+Assumptions!E22)/(Assumptions!E5+Assumptions!E6) -> 0.2625
A5: Costi operativi | B5: ='SRL P&L'!B25 -> 40000 | C5: ='SSD P&L'!B14 -> 700000 | D5: =Immobiliare!B8 -> -80000 | E5: =SUM(Assumptions!E11:E24) -> 1058311.5 | G5: Energia % | H5: =IFERROR(Assumptions!E12/'SRL P&L'!B9,"-") -> 0.053875164 | J5: =Assumptions!E12/(Assumptions!E5+Assumptions!E6) -> 0.047814208
A6: EBITDA | B6: ='SRL P&L'!B34 -> 860688.52 | C6: ='SSD P&L'!B16 -> 0 | D6: =Immobiliare!B11 -> 370000 | E6: =E4-E5 -> 1341688.5 | G6: Acqua % | H6: =IFERROR(Assumptions!E13/'SRL P&L'!B9,"-") -> 0.011544678 | J6: =Assumptions!E13/(Assumptions!E5+Assumptions!E6) -> 0.010245902
A7: EBITDA % | B7: =IF(B4=0,0,B6/B4) -> 0.40407912 | C7: =IF(C4=0,0,C6/C4) -> 0 | D7: =IF(D4=0,0,D6/D4) -> 0.82222222 | E7: =IF(E4=0,0,E6/E4) -> 0.55903689 | G7: Pulizie % | H7: =IFERROR(Assumptions!E14/'SRL P&L'!B9,"-") -> 0.03848226 | J7: =Assumptions!E14/(Assumptions!E5+Assumptions!E6) -> 0.034153005
A8: IVA netta SRL | B8: ='SRL P&L'!G11 -> 232828.52 | G8: Marketing % | H8: =IFERROR(Assumptions!E18/'SRL P&L'!B9,"-") -> 0.014084507 | J8: =Assumptions!E18/(Assumptions!E5+Assumptions!E6) -> 0.0125
A9: IVA non detraibile SSD | C9: ='SSD P&L'!G6 -> 94600 | G9: Software % | H9: =IFERROR(Assumptions!E19/'SRL P&L'!B9,"-") -> 0.014084507 | J9: =Assumptions!E19/(Assumptions!E5+Assumptions!E6) -> 0.0125
A10: Cash IVA totale non recuperabile | E10: =B8+C9 -> 327428.52 | G10: Manutenzione % | H10: =IFERROR(Assumptions!E20/'SRL P&L'!B9,"-") -> 0.014084507 | J10: =Assumptions!E20/(Assumptions!E5+Assumptions!E6) -> 0.0125
A11: Ammortamenti | B11: ='SRL P&L'!B35 -> -200000 | D11: =Immobiliare!B10 -> -100000
A12: EBIT | B12: ='SRL P&L'!B36 -> 660688.52 | D12: =Immobiliare!B12 -> 270000 | E12: =B12+D12 -> 930688.52
A13: IRES (24%) | B13: ='SRL P&L'!B37 -> -158565.25 | D13: =Immobiliare!B13 -> -64800 | E13: =B13+D13 -> -223365.25
A14: IRAP (3.9%) SRL | B14: ='SRL P&L'!B38 -> -25766.852
A15: Utile netto | B15: ='SRL P&L'!B39 -> 476356.43 | D15: =Immobiliare!B14 -> 205200 | E15: =B15+D15 -> 681556.43
A16: Utile netto % | B16: =IF(B4=0,0,B15/B4) -> 0.22364151 | D16: =IF(D4=0,0,D15/D4) -> 0.456 | E16: =IF(E4=0,0,E15/E4) -> 0.28398184
A17: * Consolidato: ricavi esterni 2,4 mln. Partite infragruppo eliminate. Costi immobiliare ora inclusi (operativi + ammortamenti 180k). | G17: Canone immob % | H17: =IFERROR((Assumptions!E9+Assumptions!E10)/'SRL P&L'!B9,"-") -> 0.21126761 | J17: =(Assumptions!E9+Assumptions!E10)/(Assumptions!E5+Assumptions!E6) -> 0.1875
G18: Servizi+spazi SSD % | H18: =IFERROR((Assumptions!E7+Assumptions!E8)/'SRL P&L'!B9,"-") -> 0.20187793 | I18: =(Assumptions!E7+Assumptions!E8)/'SSD P&L'!B5 -> 0.61428571
